<?xml version="1.0"?>
<robot name="Praetorian">

  <material name="red">
    <color rgba="0.8 0 0 1"/>
  </material>
  <material name="black">
    <color rgba="0 0 0 1"/>
  </material>
  <material name="white">
    <color rgba="1 1 1 1"/>
  </material>

  <link name="body">
    <visual>
      <geometry>
        <box size="0.385 0.12 0.08"/>
      </geometry>
          <material name="black"/>
    </visual>
  </link>
  
  <link name="right_fwheel">
      <visual>
          <origin xyz="0 0 0" rpy="1.5 0 0"/>
          <geometry>
              <cylinder radius="0.065" length="0.06"/>
          </geometry>
          <material name="black"/>
      </visual>
  </link>

  <joint name="body_to_right_fwheel" type="continuous">
    <parent link="body"/>
    <child link="right_fwheel"/>
    <origin xyz="0.16 -0.1 -0.01"/>
  </joint>

  <link name="right_mwheel">
      <visual>
          <origin xyz="0 0 0" rpy="1.5 0 0"/>
          <geometry>
              <cylinder radius="0.065" length="0.06"/>
          </geometry>
          <material name="black"/>
      </visual>
  </link>

  <joint name="body_to_right_mwheel" type="continuous">
    <parent link="body"/>
    <child link="right_mwheel"/>
    <origin xyz="0 -0.1 -0.01"/>
  </joint>

  <link name="right_bwheel">
      <visual>
          <origin xyz="0 0 0" rpy="1.5 0 0"/>
          <geometry>
              <cylinder radius="0.065" length="0.06"/>
          </geometry>
          <material name="black"/>
      </visual>
  </link>

  <joint name="body_to_right_bwheel" type="continuous">
    <parent link="body"/>
    <child link="right_bwheel"/>
    <origin xyz="-0.16 -0.1 -0.01"/>
  </joint>



  <link name="left_fwheel">
      <visual>
          <origin xyz="0 0 0" rpy="-1.5 0 0"/>
          <geometry>
              <cylinder radius="0.065" length="0.06"/>
          </geometry>
          <material name="black"/>
      </visual>
  </link>

  <joint name="body_to_left_fwheel" type="continuous">
    <parent link="body"/>
    <child link="left_fwheel"/>
    <origin xyz="0.16 0.1 -0.01"/>
  </joint>

  <link name="left_mwheel">
      <visual>
          <origin xyz="0 0 0" rpy="-1.5 0 0"/>
          <geometry>
              <cylinder radius="0.065" length="0.06"/>
          </geometry>
          <material name="black"/>
      </visual>
  </link>

  <joint name="body_to_left_mwheel" type="continuous">
    <parent link="body"/>
    <child link="left_mwheel"/>
    <origin xyz="0 0.1 -0.01"/>
  </joint>

  <link name="left_bwheel">
      <visual>
          <origin xyz="0 0 0" rpy="-1.5 0 0"/>
          <geometry>
              <cylinder radius="0.065" length="0.06"/>
          </geometry>
          <material name="black"/>
      </visual>
  </link>

  <joint name="body_to_left_bwheel" type="continuous">
    <parent link="body"/>
    <child link="left_bwheel"/>
    <origin xyz="-0.16 0.1 -0.01"/>
  </joint>

  
</robot>
